Workbook

Sheet Dashboard
A1: AstroMarket Dashboard — first trading day Tuesday 27 Oct 2026
A2: Today = that session · Short = next 5 sessions (averaged) · Long = next 40 sessions (averaged)
A4: Sky | B4: Candra Meṣa 24°40′ · Bharaṇī · opening lagna Vṛścika 14°14′
A5: Business cycle | B5: Over-expansion & boom [ACTIVE] — Śani Mīna 15°22′ R, Guru Karkaṭa 29°29′
A6: Book guidance | B6: Śani in watery rāśi aspected by Guru – euphoria; book advises booking profits and holding cash.
G7: Confidence = shrunk historical hit-rate of comparable calls (same target, horizon, strength). ~50% means no demonstrated edge.
A8: Target | B8: Intraday | C8: Short | D8: Long | E8: Composite | F8: Call | G8: Intraday conf. | H8: Short conf. | I8: Long conf.
A9: Nifty 50 (market) | B9: -0.493 | C9: 0.203 | D9: 0.065 | E9: =Settings!$C$5*B9+Settings!$C$6*C9+Settings!$C$7*D9 -> -0.1726 | F9: =IF(E9>Settings!$C$4,"Bullish",IF(E9<-Settings!$C$4,"Bearish","Neutral")) -> Bearish | G9: 0.529 | H9: 0.495
A10: Agriculture & agro industries | B10: -0.515 | C10: 0.142 | D10: -0.008 | E10: =Settings!$C$5*B10+Settings!$C$6*C10+Settings!$C$7*D10 -> -0.2165 | F10: =IF(E10>Settings!$C$4,"Bullish",IF(E10<-Settings!$C$4,"Bearish","Neutral")) -> Bearish | G10: 0.485
A11: Automobile | B11: 0.003 | C11: 0.032 | D11: 0.002 | E11: =Settings!$C$5*B11+Settings!$C$6*C11+Settings!$C$7*D11 -> 0.0115 | F11: =IF(E11>Settings!$C$4,"Bullish",IF(E11<-Settings!$C$4,"Bearish","Neutral")) -> Neutral
A12: Aviation | B12: 0.07 | C12: 0.032 | D12: 0.088 | E12: =Settings!$C$5*B12+Settings!$C$6*C12+Settings!$C$7*D12 -> 0.0622 | F12: =IF(E12>Settings!$C$4,"Bullish",IF(E12<-Settings!$C$4,"Bearish","Neutral")) -> Neutral
A13: Banking & financial | B13: -0.711 | C13: 0.146 | D13: 0.112 | E13: =Settings!$C$5*B13+Settings!$C$6*C13+Settings!$C$7*D13 -> -0.2893 | F13: =IF(E13>Settings!$C$4,"Bullish",IF(E13<-Settings!$C$4,"Bearish","Neutral")) -> Bearish | G13: 0.488
A14: Capital goods | B14: 0.069 | C14: 0.032 | D14: 0.049 | E14: =Settings!$C$5*B14+Settings!$C$6*C14+Settings!$C$7*D14 -> 0.0539 | F14: =IF(E14>Settings!$C$4,"Bullish",IF(E14<-Settings!$C$4,"Bearish","Neutral")) -> Neutral
A15: Cement | B15: 0.026 | C15: 0.097 | D15: -0.054 | E15: =Settings!$C$5*B15+Settings!$C$6*C15+Settings!$C$7*D15 -> 0.0313 | F15: =IF(E15>Settings!$C$4,"Bullish",IF(E15<-Settings!$C$4,"Bearish","Neutral")) -> Neutral
A16: Crude oil & gas | B16: 0.059 | C16: 0.233 | D16: -0.159 | E16: =Settings!$C$5*B16+Settings!$C$6*C16+Settings!$C$7*D16 -> 0.0676 | F16: =IF(E16>Settings!$C$4,"Bullish",IF(E16<-Settings!$C$4,"Bearish","Neutral")) -> Neutral | H16: 0.523 | I16: 0.448
A17: Eatable oil | B17: 0.129 | C17: 0.032 | D17: -0.005 | E17: =Settings!$C$5*B17+Settings!$C$6*C17+Settings!$C$7*D17 -> 0.0731 | F17: =IF(E17>Settings!$C$4,"Bullish",IF(E17<-Settings!$C$4,"Bearish","Neutral")) -> Neutral
A18: Educational | B18: -0.402 | C18: 0.032 | D18: 0.101 | E18: =Settings!$C$5*B18+Settings!$C$6*C18+Settings!$C$7*D18 -> -0.1712 | F18: =IF(E18>Settings!$C$4,"Bullish",IF(E18<-Settings!$C$4,"Bearish","Neutral")) -> Bearish | G18: 0.516
A19: Essential oils & perfumeries | B19: -0.778 | C19: -0.047 | D19: 0.128 | E19: =Settings!$C$5*B19+Settings!$C$6*C19+Settings!$C$7*D19 -> -0.3775 | F19: =IF(E19>Settings!$C$4,"Bullish",IF(E19<-Settings!$C$4,"Bearish","Neutral")) -> Bearish | G19: 0.506
A20: Exports | B20: -0.252 | C20: 0.032 | D20: -0.005 | E20: =Settings!$C$5*B20+Settings!$C$6*C20+Settings!$C$7*D20 -> -0.1174 | F20: =IF(E20>Settings!$C$4,"Bullish",IF(E20<-Settings!$C$4,"Bearish","Neutral")) -> Neutral | G20: 0.518
A21: FMCG | B21: -0.459 | C21: 0.284 | D21: 0.092 | E21: =Settings!$C$5*B21+Settings!$C$6*C21+Settings!$C$7*D21 -> -0.1259 | F21: =IF(E21>Settings!$C$4,"Bullish",IF(E21<-Settings!$C$4,"Bearish","Neutral")) -> Neutral | G21: 0.482 | H21: 0.531
A22: Gems & jewelry | B22: -0.439 | C22: 0.127 | D22: 0.468 | E22: =Settings!$C$5*B22+Settings!$C$6*C22+Settings!$C$7*D22 -> -0.0878 | F22: =IF(E22>Settings!$C$4,"Bullish",IF(E22<-Settings!$C$4,"Bearish","Neutral")) -> Neutral | G22: 0.478 | I22: 0.578
A23: Health care | B23: -0.544 | C23: -0.182 | D23: 0.002 | E23: =Settings!$C$5*B23+Settings!$C$6*C23+Settings!$C$7*D23 -> -0.3262 | F23: =IF(E23>Settings!$C$4,"Bullish",IF(E23<-Settings!$C$4,"Bearish","Neutral")) -> Bearish | G23: 0.517 | H23: 0.536
A24: Hospitality | B24: -0.691 | C24: -0.202 | D24: 0.132 | E24: =Settings!$C$5*B24+Settings!$C$6*C24+Settings!$C$7*D24 -> -0.3797 | F24: =IF(E24>Settings!$C$4,"Bullish",IF(E24<-Settings!$C$4,"Bearish","Neutral")) -> Bearish | G24: 0.504 | H24: 0.484
A25: Infrastructure | B25: 0.02 | C25: 0.052 | D25: -0.145 | E25: =Settings!$C$5*B25+Settings!$C$6*C25+Settings!$C$7*D25 -> -0.0034 | F25: =IF(E25>Settings!$C$4,"Bullish",IF(E25<-Settings!$C$4,"Bearish","Neutral")) -> Neutral
A26: IT | B26: 0.038 | C26: 0.032 | D26: 0.073 | E26: =Settings!$C$5*B26+Settings!$C$6*C26+Settings!$C$7*D26 -> 0.0432 | F26: =IF(E26>Settings!$C$4,"Bullish",IF(E26<-Settings!$C$4,"Bearish","Neutral")) -> Neutral
A27: Leather & footwear | B27: 0.181 | C27: 0.032 | D27: -0.339 | E27: =Settings!$C$5*B27+Settings!$C$6*C27+Settings!$C$7*D27 -> 0.0323 | F27: =IF(E27>Settings!$C$4,"Bullish",IF(E27<-Settings!$C$4,"Bearish","Neutral")) -> Neutral | G27: 0.457 | I27: 0.334
A28: Media & entertainment | B28: -0.781 | C28: -0.121 | D28: 0.363 | E28: =Settings!$C$5*B28+Settings!$C$6*C28+Settings!$C$7*D28 -> -0.3542 | F28: =IF(E28>Settings!$C$4,"Bullish",IF(E28<-Settings!$C$4,"Bearish","Neutral")) -> Bearish | G28: 0.52 | I28: 0.431
A29: Metal | B29: 0.104 | C29: 0.097 | D29: -0.048 | E29: =Settings!$C$5*B29+Settings!$C$6*C29+Settings!$C$7*D29 -> 0.0715 | F29: =IF(E29>Settings!$C$4,"Bullish",IF(E29<-Settings!$C$4,"Bearish","Neutral")) -> Neutral
A30: Paints | B30: -0.468 | C30: -0.202 | D30: 0.132 | E30: =Settings!$C$5*B30+Settings!$C$6*C30+Settings!$C$7*D30 -> -0.2682 | F30: =IF(E30>Settings!$C$4,"Bullish",IF(E30<-Settings!$C$4,"Bearish","Neutral")) -> Bearish | G30: 0.527 | H30: 0.513
A31: Pharmaceutical | B31: -0.261 | C31: 0.032 | D31: -0.126 | E31: =Settings!$C$5*B31+Settings!$C$6*C31+Settings!$C$7*D31 -> -0.1461 | F31: =IF(E31>Settings!$C$4,"Bullish",IF(E31<-Settings!$C$4,"Bearish","Neutral")) -> Neutral | G31: 0.527
A32: Power | B32: -0.151 | C32: 0.021 | D32: 0.094 | E32: =Settings!$C$5*B32+Settings!$C$6*C32+Settings!$C$7*D32 -> -0.0504 | F32: =IF(E32>Settings!$C$4,"Bullish",IF(E32<-Settings!$C$4,"Bearish","Neutral")) -> Neutral | G32: 0.493
A33: Publication | B33: 0.038 | C33: 0.032 | D33: 0.101 | E33: =Settings!$C$5*B33+Settings!$C$6*C33+Settings!$C$7*D33 -> 0.0488 | F33: =IF(E33>Settings!$C$4,"Bullish",IF(E33<-Settings!$C$4,"Bearish","Neutral")) -> Neutral
A34: Realty | B34: 0.217 | C34: 0.052 | D34: -0.145 | E34: =Settings!$C$5*B34+Settings!$C$6*C34+Settings!$C$7*D34 -> 0.0951 | F34: =IF(E34>Settings!$C$4,"Bullish",IF(E34<-Settings!$C$4,"Bearish","Neutral")) -> Neutral | G34: 0.468
A35: Shipping | B35: 0.161 | C35: 0.184 | D35: -0.015 | E35: =Settings!$C$5*B35+Settings!$C$6*C35+Settings!$C$7*D35 -> 0.1327 | F35: =IF(E35>Settings!$C$4,"Bullish",IF(E35<-Settings!$C$4,"Bearish","Neutral")) -> Neutral | G35: 0.5 | H35: 0.439
A36: Sugar | B36: -0.789 | C36: -0.202 | D36: 0.08 | E36: =Settings!$C$5*B36+Settings!$C$6*C36+Settings!$C$7*D36 -> -0.4391 | F36: =IF(E36>Settings!$C$4,"Bullish",IF(E36<-Settings!$C$4,"Bearish","Neutral")) -> Bearish | G36: 0.498 | H36: 0.515
A37: Telecommunication | B37: -0.161 | C37: 0.424 | D37: 0.077 | E37: =Settings!$C$5*B37+Settings!$C$6*C37+Settings!$C$7*D37 -> 0.0621 | F37: =IF(E37>Settings!$C$4,"Bullish",IF(E37<-Settings!$C$4,"Bearish","Neutral")) -> Neutral | G37: 0.483 | H37: 0.528
A38: Textile | B38: -0.456 | C38: 0.146 | D38: 0.112 | E38: =Settings!$C$5*B38+Settings!$C$6*C38+Settings!$C$7*D38 -> -0.1618 | F38: =IF(E38>Settings!$C$4,"Bullish",IF(E38<-Settings!$C$4,"Bearish","Neutral")) -> Bearish | G38: 0.511
A39: Travel & tourism | B39: -0.642 | C39: 0.152 | D39: 0.157 | E39: =Settings!$C$5*B39+Settings!$C$6*C39+Settings!$C$7*D39 -> -0.244 | F39: =IF(E39>Settings!$C$4,"Bullish",IF(E39<-Settings!$C$4,"Bearish","Neutral")) -> Bearish | G39: 0.444 | H39: 0.466 | I39: 0.463
A40: Gov. public sector units (PSU) | B40: -0.23 | C40: 0.032 | D40: -0.054 | E40: =Settings!$C$5*B40+Settings!$C$6*C40+Settings!$C$7*D40 -> -0.1162 | F40: =IF(E40>Settings!$C$4,"Bullish",IF(E40<-Settings!$C$4,"Bearish","Neutral")) -> Neutral | G40: 0.478
A41: Gold | B41: 0.059 | C41: 0.642 | D41: 0.752 | E41: =Settings!$C$5*B41+Settings!$C$6*C41+Settings!$C$7*D41 -> 0.3725 | F41: =IF(E41>Settings!$C$4,"Bullish",IF(E41<-Settings!$C$4,"Bearish","Neutral")) -> Bullish | H41: 0.442 | I41: 0.522
...

Sheet Settings
A1: Settings & legend
A2: Yellow cells are inputs. Change them and every call, colour and tracker statistic in the workbook updates.
B3: Parameter | C3: Value | D3: Note
B4: Green / Red threshold (|score| above which a call is Bullish / Bearish) | C4: 0.15 | D4: Engine default 0.15. Scores run −1 … +1.
B5: Overall-view weight — today | C5: 0.5 | D5: Overall = w·today + w·next week + w·next 2 months (pre-computed in Daily_Composite with these defaults).
B6: Overall-view weight — next week | C6: 0.3
B7: Overall-view weight — next 2 months | C7: 0.2
B8: Workbook generated | C8: 2026-10-26 16:31 | D8: Re-run build_excel.py to roll forward.
B9: Market location / opening bell | C9: NSE/BSE Mumbai 09:15 | D9: Opening-bell chart & horā computed for this place.
B12: Legend
C13: Bullish (score > threshold)
C14: Neutral (|score| ≤ threshold)
C15: Bearish (score < −threshold)
C16: Input cell (blue text) — edit me
B18: Important
B19: Backtest 2012-02-21 → 2026-10-23 on NSE indices: intraday directional hit-rate 50.5% (95% CI 50.0–51.0%), short-term 50.5%, long-term 46.1% vs ~60% for a naive "always up" call. Treat outputs as an implementation of the book, not as a validated trading signal.

Sheet Grid_12M
A1: Day-box grid — 12 months × all sectors & commodities (daily composite)
A2: Each box links to Daily_Composite; green = Bullish, amber = Neutral, red = Bearish. Weekend columns shaded headers.
B3: Oct-26 | G3: Nov-26 | AK3: Dec-26 | BP3: Jan-27 | CU3: Feb-27 | DW3: Mar-27 | FB3: Apr-27 | GF3: May-27 | HK3: Jun-27 | IO3: Jul-27 | JT3: Aug-27 | KY3: Sep-27 | MC3: Oct-27
A4: Target | B4: 27 | C4: 28 | D4: 29 | E4: 30 | F4: 31 | G4: 1 | H4: 2 | I4: 3 | J4: 4 | K4: 5 | L4: 6 | M4: 7 | N4: 8 | O4: 9 | P4: 10 | Q4: 11 | R4: 12 | S4: 13 | T4: 14 | U4: 15 | V4: 16 | W4: 17 | X4: 18 | Y4: 19 | Z4: 20 | AA4: 21 | AB4: 22 | AC4: 23 | AD4: 24 | AE4: 25 | AF4: 26 | AG4: 27 | AH4: 28 | AI4: 29 | AJ4: 30 | AK4: 1 | AL4: 2 | AM4: 3 | AN4: 4 | AO4: 5 | AP4: 6 | AQ4: 7 | AR4: 8 | AS4: 9 | AT4: 10 | AU4: 11 | AV4: 12 | AW4: 13 | AX4: 14 | AY4: 15 | AZ4: 16 | BA4: 17 | BB4: 18 | BC4: 19 | BD4: 20 | BE4: 21 | BF4: 22 | BG4: 23 | BH4: 24 | BI4: 25 | BJ4: 26 | BK4: 27 | BL4: 28 | BM4: 29 | BN4: 30 | BO4: 31 | BP4: 1 | BQ4: 2 | BR4: 3 | BS4: 4 | BT4: 5 | BU4: 6 | BV4: 7 | BW4: 8 | BX4: 9 | BY4: 10 | BZ4: 11 | CA4: 12 | CB4: 13 | CC4: 14 | CD4: 15 | CE4: 16 | CF4: 17 | CG4: 18 | CH4: 19 | CI4: 20 | CJ4: 21 | CK4: 22 | CL4: 23 | CM4: 24 | CN4: 25 | CO4: 26 | CP4: 27 | CQ4: 28 | CR4: 29 | CS4: 30 | CT4: 31 | CU4: 1 | CV4: 2 | CW4: 3 | CX4: 4 | CY4: 5 | CZ4: 6 | DA4: 7 | DB4: 8 | DC4: 9 | DD4: 10 | DE4: 11 | DF4: 12 | DG4: 13 | DH4: 14 | DI4: 15 | DJ4: 16 | DK4: 17 | DL4: 18 | DM4: 19 | DN4: 20 | DO4: 21 | DP4: 22 | DQ4: 23 | DR4: 24 | DS4: 25 | DT4: 26 | DU4: 27 | DV4: 28 | DW4: 1 | DX4: 2 | DY4: 3 | DZ4: 4 | EA4: 5 | EB4: 6 | EC4: 7 | ED4: 8 | EE4: 9 | EF4: 10 | EG4: 11 | EH4: 12 | EI4: 13 | EJ4: 14 | EK4: 15 | EL4: 16 | EM4: 17 | EN4: 18 | EO4: 19 | EP4: 20 | EQ4: 21 | ER4: 22 | ES4: 23 | ET4: 24 | EU4: 25 | EV4: 26 | EW4: 27 | EX4: 28 | EY4: 29 | EZ4: 30 | FA4: 31 | FB4: 1 | FC4: 2 | FD4: 3 | FE4: 4 | FF4: 5 | FG4: 6 | FH4: 7 | FI4: 8 | FJ4: 9 | FK4: 10 | FL4: 11 | FM4: 12 | FN4: 13 | FO4: 14 | FP4: 15 | FQ4: 16 | FR4: 17 | FS4: 18 | FT4: 19 | FU4: 20 | FV4: 21 | FW4: 22 | FX4: 23 | FY4: 24 | FZ4: 25 | GA4: 26 | GB4: 27 | GC4: 28 | GD4: 29 | GE4: 30 | GF4: 1 | GG4: 2 | GH4: 3 | GI4: 4 | GJ4: 5 | GK4: 6 | GL4: 7 | GM4: 8 | GN4: 9 | GO4: 10 | GP4: 11 | GQ4: 12 | GR4: 13 | GS4: 14 | GT4: 15 | GU4: 16 | GV4: 17 | GW4: 18 | GX4: 19 | GY4: 20 | GZ4: 21 | HA4: 22 | HB4: 23 | HC4: 24 | HD4: 25 | HE4: 26 | HF4: 27 | HG4: 28 | HH4: 29 | HI4: 30 | HJ4: 31 | HK4: 1 | HL4: 2 | HM4: 3 | HN4: 4 | HO4: 5 | HP4: 6 | HQ4: 7 | HR4: 8 | HS4: 9 | HT4: 10 | HU4: 11 | HV4: 12 | HW4: 13 | HX4: 14 | HY4: 15 | HZ4: 16 | IA4: 17 | IB4: 18 | IC4: 19 | ID4: 20 | IE4: 21 | IF4: 22 | IG4: 23 | IH4: 24 | II4: 25 | IJ4: 26 | IK4: 27 | IL4: 28 | IM4: 29 | IN4: 30 | IO4: 1 | IP4: 2 | IQ4: 3 | IR4: 4 | IS4: 5 | IT4: 6 | IU4: 7 | IV4: 8 | IW4: 9 | IX4: 10 | IY4: 11 | IZ4: 12 | JA4: 13 | JB4: 14 | JC4: 15 | JD4: 16 | JE4: 17 | JF4: 18 | JG4: 19 | JH4: 20 | JI4: 21 | JJ4: 22 | JK4: 23 | JL4: 24 | JM4: 25 | JN4: 26 | JO4: 27 | JP4: 28 | JQ4: 29 | JR4: 30 | JS4: 31 | JT4: 1 | JU4: 2 | JV4: 3 | JW4: 4 | JX4: 5 | JY4: 6 | JZ4: 7 | KA4: 8 | KB4: 9 | KC4: 10 | KD4: 11 | KE4: 12 | KF4: 13 | KG4: 14 | KH4: 15 | KI4: 16 | KJ4: 17 | KK4: 18 | KL4: 19 | KM4: 20 | KN4: 21 | KO4: 22 | KP4: 23 | KQ4: 24 | KR4: 25 | KS4: 26 | KT4: 27 | KU4: 28 | KV4: 29 | KW4: 30 | KX4: 31 | KY4: 1 | KZ4: 2 | LA4: 3 | LB4: 4 | LC4: 5 | LD4: 6 | LE4: 7 | LF4: 8 | LG4: 9 | LH4: 10 | LI4: 11 | LJ4: 12 | LK4: 13 | LL4: 14 | LM4: 15 | LN4: 16 | LO4: 17 | LP4: 18 | LQ4: 19 | LR4: 20 | LS4: 21 | LT4: 22 | LU4: 23 | LV4: 24 | LW4: 25 | LX4: 26 | LY4: 27 | LZ4: 28 | MA4: 29 | MB4: 30 | MC4: 1 | MD4: 2 | ME4: 3 | MF4: 4 | MG4: 5 | MH4: 6 | MI4: 7 | MJ4: 8 | MK4: 9 | ML4: 10 | MM4: 11 | MN4: 12 | MO4: 13 | MP4: 14 | MQ4: 15 | MR4: 16 | MS4: 17 | MT4: 18 | MU4: 19 | MV4: 20 | MW4: 21 | MX4: 22 | MY4: 23 | MZ4: 24 | NA4: 25 | NB4: 26
A5: Nifty 50 (market) | B5: =Daily_Composite!G5 -> -0.173 | C5: =Daily_Composite!G6 -> 0.04 | D5: =Daily_Composite!G7 -> 0.009 | E5: =Daily_Composite!G8 -> -0.07 | F5: =Daily_Composite!G9 -> -0.326 | G5: =Daily_Composite!G10 -> -0.215 | H5: =Daily_Composite!G11 -> 0.159 | I5: =Daily_Composite!G12 -> -0.356 | J5: =Daily_Composite!G13 -> 0.047 | K5: =Daily_Composite!G14 -> -0.028 | L5: =Daily_Composite!G15 -> -0.205 | M5: =Daily_Composite!G16 -> -0.179 | N5: =Daily_Composite!G17 -> -0.227 | O5: =Daily_Composite!G18 -> -0.235 | P5: =Daily_Composite!G19 -> 0.005 | Q5: =Daily_Composite!G20 -> -0.029 | R5: =Daily_Composite!G21 -> 0.507 | S5: =Daily_Composite!G22 -> -0.016 | T5: =Daily_Composite!G23 -> 0.461 | U5: =Daily_Composite!G24 -> 0.145 | V5: =Daily_Composite!G25 -> 0.186 | W5: =Daily_Composite!G26 -> -0.031 | X5: =Daily_Composite!G27 -> -0.146 | Y5: =Daily_Composite!G28 -> 0.28 | Z5: =Daily_Composite!G29 -> 0.082 | AA5: =Daily_Composite!G30 -> 0.337 | AB5: =Daily_Composite!G31 -> -0.141 | AC5: =Daily_Composite!G32 -> 0.168 | AD5: =Daily_Composite!G33 -> 0.307 | AE5: =Daily_Composite!G34 -> 0.259 | AF5: =Daily_Composite!G35 -> 0.531 | AG5: =Daily_Composite!G36 -> 0.473 | AH5: =Daily_Composite!G37 -> 0.485 | AI5: =Daily_Composite!G38 -> 0.52 | AJ5: =Daily_Composite!G39 -> 0.369 | AK5: =Daily_Composite!G40 -> 0.524 | AL5: =Daily_Composite!G41 -> 0.279 | AM5: =Daily_Composite!G42 -> 0.058 | AN5: =Daily_Composite!G43 -> 0.346 | AO5: =Daily_Composite!G44 -> -0.049 | AP5: =Daily_Composite!G45 -> 0.142 | AQ5: =Daily_Composite!G46 -> 0.508 | AR5: =Daily_Composite!G47 -> 0.04 | AS5: =Daily_Composite!G48 -> 0.07 | AT5: =Daily_Composite!G49 -> 0.086 | AU5: =Daily_Composite!G50 -> 0.348 | AV5: =Daily_Composite!G51 -> 0.161 | AW5: =Daily_Composite!G52 -> -0.064 | AX5: =Daily_Composite!G53 -> 0.135 | AY5: =Daily_Composite!G54 -> -0.088 | AZ5: =Daily_Composite!G55 -> -0.11 | BA5: =Daily_Composite!G56 -> 0.294 | BB5: =Daily_Composite!G57 -> -0.094 | BC5: =Daily_Composite!G58 -> -0.273 | BD5: =Daily_Composite!G59 -> 0.202 | BE5: =Daily_Composite!G60 -> -0.179 | BF5: =Daily_Composite!G61 -> 0.021 | BG5: =Daily_Composite!G62 -> 0.325 | BH5: =Daily_Composite!G63 -> -0.001 | BI5: =Daily_Composite!G64 -> 0.194 | BJ5: =Daily_Composite!G65 -> -0.157 | BK5: =Daily_Composite!G66 -> 0.088 | BL5: =Daily_Composite!G67 -> 0.08 | BM5: =Daily_Composite!G68 -> 0.202 | BN5: =Daily_Composite!G69 -> 0.062 | BO5: =Daily_Composite!G70 -> -0.094 | BP5: =Daily_Composite!G71 -> -0.01 | BQ5: =Daily_Composite!G72 -> -0.035 | BR5: =Daily_Composite!G73 -> 0.151 | BS5: =Daily_Composite!G74 -> -0.191 | BT5: =Daily_Composite!G75 -> 0.156 | BU5: =Daily_Composite!G76 -> -0.04 | BV5: =Daily_Composite!G77 -> -0.048 | BW5: =Daily_Composite!G78 -> 0.065 | BX5: =Daily_Composite!G79 -> -0.217 | BY5: =Daily_Composite!G80 -> -0.237 | BZ5: =Daily_Composite!G81 -> 0.188 | CA5: =Daily_Composite!G82 -> -0.01 | CB5: =Daily_Composite!G83 -> 0.251 | CC5: =Daily_Composite!G84 -> -0.2 | CD5: =Daily_Composite!G85 -> 0.367 | CE5: =Daily_Composite!G86 -> 0.179 | CF5: =Daily_Composite!G87 -> 0.47 | CG5: =Daily_Composite!G88 -> -0.224 | CH5: =Daily_Composite!G89 -> -0.249 | CI5: =Daily_Composite!G90 -> 0.285 | CJ5: =Daily_Composite!G91 -> 0.216 | CK5: =Daily_Composite!G92 -> -0.132 | CL5: =Daily_Composite!G93 -> -0.245 | CM5: =Daily_Composite!G94 -> 0.204 | CN5: =Daily_Composite!G95 -> -0.36 | CO5: =Daily_Composite!G96 -> -0.343 | CP5: =Daily_Composite!G97 -> -0.454 | CQ5: =Daily_Composite!G98 -> -0.631 | CR5: =Daily_Composite!G99 -> -0.64 | CS5: =Daily_Composite!G100 -> -0.617 | CT5: =Daily_Composite!G101 -> -0.535 | CU5: =Daily_Composite!G102 -> -0.648 | CV5: =Daily_Composite!G103 -> -0.663 | CW5: =Daily_Composite!G104 -> -0.676 | CX5: =Daily_Composite!G105 -> -0.655 | CY5: =Daily_Composite!G106 -> -0.553 | CZ5: =Daily_Composite!G107 -> -0.555 | DA5: =Daily_Composite!G108 -> -0.626 | DB5: =Daily_Composite!G109 -> -0.603 | DC5: =Daily_Composite!G110 -> -0.595 | DD5: =Daily_Composite!G111 -> -0.277 | DE5: =Daily_Composite!G112 -> -0.593 | DF5: =Daily_Composite!G113 -> -0.554 | DG5: =Daily_Composite!G114 -> -0.39 | DH5: =Daily_Composite!G115 -> -0.479 | DI5: =Daily_Composite!G116 -> -0.608 | DJ5: =Daily_Composite!G117 -> -0.69 | DK5: =Daily_Composite!G118 -> -0.685 | DL5: =Daily_Composite!G119 -> -0.592 | DM5: =Daily_Composite!G120 -> -0.33 | DN5: =Daily_Composite!G121 -> -0.554 | DO5: =Daily_Composite!G122 -> -0.427 | DP5: =Daily_Composite!G123 -> -0.271 | DQ5: =Daily_Composite!G124 -> -0.415 | DR5: =Daily_Composite!G125 -> -0.039 | DS5: =Daily_Composite!G126 -> -0.112 | DT5: =Daily_Composite!G127 -> -0.293 | DU5: =Daily_Composite!G128 -> 0.117 | DV5: =Daily_Composite!G129 -> -0.023 | DW5: =Daily_Composite!G130 -> 0.552 | DX5: =Daily_Composite!G131 -> 0.209 | DY5: =Daily_Composite!G132 -> 0.036 | DZ5: =Daily_Composite!G133 -> -0.076 | EA5: =Daily_Composite!G134 -> -0.196 | EB5: =Daily_Composite!G135 -> 0.095 | EC5: =Daily_Composite!G136 -> -0.054 | ED5: =Daily_Composite!G137 -> -0.366 | EE5: =Daily_Composite!G138 -> -0.117 | EF5: =Daily_Composite!G139 -> 0.136 | EG5: =Daily_Composite!G140 -> 0.238 | EH5: =Daily_Composite!G141 -> -0.143 | EI5: =Daily_Composite!G142 -> -0.019 | EJ5: =Daily_Composite!G143 -> -0.369 | EK5: =Daily_Composite!G144 -> -0.596 | EL5: =Daily_Composite!G145 -> -0.368 | EM5: =Daily_Composite!G146 -> -0.403 | EN5: =Daily_Composite!G147 -> -0.304 | EO5: =Daily_Composite!G148 -> -0.44 | EP5: =Daily_Composite!G149 -> 0.016 | EQ5: =Daily_Composite!G150 -> -0.206 | ER5: =Daily_Composite!G151 -> -0.161 | ES5: =Daily_Composite!G152 -> -0.244 | ET5: =Daily_Composite!G153 -> -0.423 | EU5: =Daily_Composite!G154 -> -0.339 | EV5: =Daily_Composite!G155 -> -0.091 | EW5: =Daily_Composite!G156 -> -0.039 | EX5: =Daily_Composite!G157 -> 0.228 | EY5: =Daily_Composite!G158 -> -0.301 | EZ5: =Daily_Composite!G159 -> 0.064 | FA5: =Daily_Composite!G160 -> -0.108 | FB5: =Daily_Composite!G161 -> -0.14 | FC5: =Daily_Composite!G162 -> 0.03 | FD5: =Daily_Composite!G163 -> -0.393 | FE5: =Daily_Composite!G164 -> -0.376 | FF5: =Daily_Composite!G165 -> 0.293 | FG5: =Daily_Composite!G166 -> -0.147 | FH5: =Daily_Composite!G167 -> 0.061 | FI5: =Daily_Composite!G168 -> -0.306 | FJ5: =Daily_Composite!G169 -> -0.023 | FK5: =Daily_Composite!G170 -> -0.076 | FL5: =Daily_Composite!G171 -> -0.194 | FM5: =Daily_Composite!G172 -> 0.034 | FN5: =Daily_Composite!G173 -> 0.05 | FO5: =Daily_Composite!G174 -> -0.203 | FP5: =Daily_Composite!G175 -> -0.076 | FQ5: =Daily_Composite!G176 -> -0.043 | FR5: =Daily_Composite!G177 -> 0.254 | FS5: =Daily_Composite!G178 -> -0.148 | FT5: =Daily_Composite!G179 -> -0.424 | FU5: =Daily_Composite!G180 -> -0.577 | FV5: =Daily_Composite!G181 -> -0.339 | FW5: =Daily_Composite!G182 -> -0.478 | FX5: =Daily_Composite!G183 -> -0.532 | FY5: =Daily_Composite!G184 -> -0.622 | FZ5: =Daily_Composite!G185 -> -0.4 | GA5: =Daily_Composite!G186 -> -0.119 | GB5: =Daily_Composite!G187 -> -0.224 | GC5: =Daily_Composite!G188 -> -0.556 | GD5: =Daily_Composite!G189 -> -0.287 | GE5: =Daily_Composite!G190 -> -0.168 | GF5: =Daily_Composite!G191 -> -0.496 | GG5: =Daily_Composite!G192 -> -0.595 | GH5: =Daily_Composite!G193 -> -0.422 | GI5: =Daily_Composite!G194 -> -0.284 | GJ5: =Daily_Composite!G195 -> 0.111 | GK5: =Daily_Composite!G196 -> 0.1 | GL5: =Daily_Composite!G197 -> -0.39 | GM5: =Daily_Composite!G198 -> -0.441 | GN5: =Daily_Composite!G199 -> -0.211 | GO5: =Daily_Composite!G200 -> -0.376 | GP5: =Daily_Composite!G201 -> -0.415 | GQ5: =Daily_Composite!G202 -> -0.384 | GR5: =Daily_Composite!G203 -> 0.121 | GS5: =Daily_Composite!G204 -> -0.401 | GT5: =Daily_Composite!G205 -> -0.222 | GU5: =Daily_Composite!G206 -> -0.417 | GV5: =Daily_Composite!G207 -> -0.357 | GW5: =Daily_Composite!G208 -> -0.369 | GX5: =Daily_Composite!G209 -> -0.446 | GY5: =Daily_Composite!G210 -> -0.386 | GZ5: =Daily_Composite!G211 -> -0.431 | HA5: =Daily_Composite!G212 -> -0.1 | HB5: =Daily_Composite!G213 -> -0.735 | HC5: =Daily_Composite!G214 -> -0.632 | HD5: =Daily_Composite!G215 -> -0.349 | HE5: =Daily_Composite!G216 -> -0.26 | HF5: =Daily_Composite!G217 -> -0.409 | HG5: =Daily_Composite!G218 -> -0.669 | HH5: =Daily_Composite!G219 -> -0.718 | HI5: =Daily_Composite!G220 -> -0.411 | HJ5: =Daily_Composite!G221 -> -0.41 | HK5: =Daily_Composite!G222 -> -0.46 | HL5: =Daily_Composite!G223 -> -0.663 | HM5: =Daily_Composite!G224 -> -0.631 | HN5: =Daily_Composite!G225 -> -0.727 | HO5: =Daily_Composite!G226 -> -0.711 | HP5: =Daily_Composite!G227 -> -0.75 | HQ5: =Daily_Composite!G228 -> -0.707 | HR5: =Daily_Composite!G229 -> -0.442 | HS5: =Daily_Composite!G230 -> -0.08 | HT5: =Daily_Composite!G231 -> -0.74 | HU5: =Daily_Composite!G232 -> -0.545 | HV5: =Daily_Composite!G233 -> -0.553 | HW5: =Daily_Composite!G234 -> -0.573 | HX5: =Daily_Composite!G235 -> -0.56 | HY5: =Daily_Composite!G236 -> -0.504 | HZ5: =Daily_Composite!G237 -> -0.347 | IA5: =Daily_Composite!G238 -> -0.29 | IB5: =Daily_Composite!G239 -> 0.147 | IC5: =Daily_Composite!G240 -> -0.202 | ID5: =Daily_Composite!G241 -> 0.025 | IE5: =Daily_Composite!G242 -> -0.263 | IF5: =Daily_Composite!G243 -> -0.21 | IG5: =Daily_Composite!G244 -> -0.196 | IH5: =Daily_Composite!G245 -> -0.083 | II5: =Daily_Composite!G246 -> -0.203 | IJ5: =Daily_Composite!G247 -> 0.304 | IK5: =Daily_Composite!G248 -> 0.295 | IL5: =Daily_Composite!G249 -> 0.515 | IM5: =Daily_Composite!G250 -> 0.196 | IN5: =Daily_Composite!G251 -> 0.512 | IO5: =Daily_Composite!G252 -> 0.104 | IP5: =Daily_Composite!G253 -> 0.131 | IQ5: =Daily_Composite!G254 -> 0.262 | IR5: =Daily_Composite!G255 -> 0.267 | IS5: =Daily_Composite!G256 -> -0.084 | IT5: =Daily_Composite!G257 -> 0.362 | IU5: =Daily_Composite!G258 -> 0.245 | IV5: =Daily_Composite!G259 -> 0.378 | IW5: =Daily_Composite!G260 -> 0.073 | IX5: =Daily_Composite!G261 -> 0.092 | IY5: =Daily_Composite!G262 -> -0.136 | IZ5: =Daily_Composite!G263 -> 0.055 | JA5: =Daily_Composite!G264 -> 0.074 | JB5: =Daily_Composite!G265 -> 0.019 | JC5: =Daily_Composite!G266 -> 0.223 | JD5: =Daily_Composite!G267 -> 0.154 | JE5: =Daily_Composite!G268 -> 0.225 | JF5: =Daily_Composite!G269 -> -0.021 | JG5: =Daily_Composite!G270 -> -0.118 | JH5: =Daily_Composite!G271 -> -0.212 | JI5: =Daily_Composite!G272 -> -0.301 | JJ5: =Daily_Composite!G273 -> -0.208 | JK5: =Daily_Composite!G274 -> -0.216 | JL5: =Daily_Composite!G275 -> -0.242 | JM5: =Daily_Composite!G276 -> 0.186 | JN5: =Daily_Composite!G277 -> -0.099 | JO5: =Daily_Composite!G278 -> -0.37 | JP5: =Daily_Composite!G279 -> -0.347 | JQ5: =Daily_Composite!G280 -> -0.418 | JR5: =Daily_Composite!G281 -> -0.411 | JS5: =Daily_Composite!G282 -> 0.181 | JT5: =Daily_Composite!G283 -> 0.11 | JU5: =Daily_Composite!G284 -> -0.248 | JV5: =Daily_Composite!G285 -> 0.294 | JW5: =Daily_Composite!G286 -> 0.32 | JX5: =Daily_Composite!G287 -> 0.054 | JY5: =Daily_Composite!G288 -> 0.138 | JZ5: =Daily_Composite!G289 -> 0.239 | KA5: =Daily_Composite!G290 -> 0.076 | KB5: =Daily_Composite!G291 -> 0.003 | KC5: =Daily_Composite!G292 -> -0.323 | KD5: =Daily_Composite!G293 -> 0.198 | KE5: =Daily_Composite!G294 -> 0.273 | KF5: =Daily_Composite!G295 -> 0.343 | KG5: =Daily_Composite!G296 -> -0.299 | KH5: =Daily_Composite!G297 -> -0.627 | KI5: =Daily_Composite!G298 -> -0.523 | KJ5: =Daily_Composite!G299 -> -0.447 | KK5: =Daily_Composite!G300 -> -0.401 | KL5: =Daily_Composite!G301 -> -0.416 | KM5: =Daily_Composite!G302 -> -0.253 | KN5: =Daily_Composite!G303 -> 0.257 | KO5: =Daily_Composite!G304 -> -0.294 | KP5: =Daily_Composite!G305 -> -0.322 | KQ5: =Daily_Composite!G306 -> -0.05 | KR5: =Daily_Composite!G307 -> -0.456 | KS5: =Daily_Composite!G308 -> -0.577 | KT5: =Daily_Composite!G309 -> -0.216 | KU5: =Daily_Composite!G310 -> -0.41 | KV5: =Daily_Composite!G311 -> -0.45 | KW5: =Daily_Composite!G312 -> -0.024 | KX5: =Daily_Composite!G313 -> -0.043 | KY5: =Daily_Composite!G314 -> -0.393 | KZ5: =Daily_Composite!G315 -> -0.284 | LA5: =Daily_Composite!G316 -> -0.32 | LB5: =Daily_Composite!G317 -> -0.247 | LC5: =Daily_Composite!G318 -> -0.136 | LD5: =Daily_Composite!G319 -> -0.066 | LE5: =Daily_Composite!G320 -> -0.1 | LF5: =Daily_Composite!G321 -> -0.042 | LG5: =Daily_Composite!G322 -> 0.068 | LH5: =Daily_Composite!G323 -> 0.469 | LI5: =Daily_Composite!G324 -> -0.005 | LJ5: =Daily_Composite!G325 -> -0.136 | LK5: =Daily_Composite!G326 -> -0.272 | LL5: =Daily_Composite!G327 -> 0.199 | LM5: =Daily_Composite!G328 -> 0.35 | LN5: =Daily_Composite!G329 -> 0.164 | LO5: =Daily_Composite!G330 -> -0.236 | LP5: =Daily_Composite!G331 -> 0.037 | LQ5: =Daily_Composite!G332 -> 0.049 | LR5: =Daily_Composite!G333 -> 0.27 | LS5: =Daily_Composite!G334 -> -0.303 | LT5: =Daily_Composite!G335 -> -0.501 | LU5: =Daily_Composite!G336 -> -0.718 | LV5: =Daily_Composite!G337 -> -0.302 | LW5: =Daily_Composite!G338 -> -0.323 | LX5: =Daily_Composite!G339 -> -0.382 | LY5: =Daily_Composite!G340 -> -0.319 | LZ5: =Daily_Composite!G341 -> -0.238 | MA5: =Daily_Composite!G342 -> -0.373 | MB5: =Daily_Composite!G343 -> -0.456 | MC5: =Daily_Composite!G344 -> -0.557 | MD5: =Daily_Composite!G345 -> -0.255 | ME5: =Daily_Composite!G346 -> -0.169 | MF5: =Daily_Composite!G347 -> 0.197 | MG5: =Daily_Composite!G348 -> 0.34 | MH5: =Daily_Composite!G349 -> 0.409 | MI5: =Daily_Composite!G350 -> 0.589 | MJ5: =Daily_Composite!G351 -> 0.664 | MK5: =Daily_Composite!G352 -> 0.385 | ML5: =Daily_Composite!G353 -> 0.412 | MM5: =Daily_Composite!G354 -> 0.429 | MN5: =Daily_Composite!G355 -> 0.136 | MO5: =Daily_Composite!G356 -> 0.442 | MP5: =Daily_Composite!G357 -> 0.646 | MQ5: =Daily_Composite!G358 -> 0.637 | MR5: =Daily_Composite!G359 -> 0.057 | MS5: =Daily_Composite!G360 -> 0.331 | MT5: =Daily_Composite!G361 -> 0.142 | MU5: =Daily_Composite!G362 -> 0.141 | MV5: =Daily_Composite!G363 -> -0.092 | MW5: =Daily_Composite!G364 -> -0.085 | MX5: =Daily_Composite!G365 -> -0.072 | MY5: =Daily_Composite!G366 -> 0.119 | MZ5: =Daily_Composite!G367 -> 0.307 | NA5: =Daily_Composite!G368 -> 0.035 | NB5: =Daily_Composite!G369 -> -0.003
A6: Agriculture & agro industries | B6: =Daily_Composite!H5 -> -0.217 | C6: =Daily_Composite!H6 -> 0.295 | D6: =Daily_Composite!H7 -> 0.125 | E6: =Daily_Composite!H8 -> 0.059 | F6: =Daily_Composite!H9 -> -0.315 | G6: =Daily_Composite!H10 -> 0.033 | H6: =Daily_Composite!H11 -> 0.451 | I6: =Daily_Composite!H12 -> 0.22 | J6: =Daily_Composite!H13 -> 0.381 | K6: =Daily_Composite!H14 -> 0.275 | L6: =Daily_Composite!H15 -> -0.16 | M6: =Daily_Composite!H16 -> 0.323 | N6: =Daily_Composite!H17 -> 0.207 | O6: =Daily_Composite!H18 -> -0.156 | P6: =Daily_Composite!H19 -> 0.549 | Q6: =Daily_Composite!H20 -> 0.417 | R6: =Daily_Composite!H21 -> 0.554 | S6: =Daily_Composite!H22 -> 0.261 | T6: =Daily_Composite!H23 -> 0.479 | U6: =Daily_Composite!H24 -> 0.231 | V6: =Daily_Composite!H25 -> 0.253 | W6: =Daily_Composite!H26 -> 0.021 | X6: =Daily_Composite!H27 -> -0.128 | Y6: =Daily_Composite!H28 -> 0.346 | Z6: =Daily_Composite!H29 -> -0.259 | AA6: =Daily_Composite!H30 -> 0.121 | AB6: =Daily_Composite!H31 -> 0.098 | AC6: =Daily_Composite!H32 -> 0.11 | AD6: =Daily_Composite!H33 -> -0.044 | AE6: =Daily_Composite!H34 -> -0.015 | AF6: =Daily_Composite!H35 -> -0.107 | AG6: =Daily_Composite!H36 -> -0.036 | AH6: =Daily_Composite!H37 -> 0.322 | AI6: =Daily_Composite!H38 -> 0.195 | AJ6: =Daily_Composite!H39 -> -0.054 | AK6: =Daily_Composite!H40 -> 0.226 | AL6: =Daily_Composite!H41 -> -0.134 | AM6: =Daily_Composite!H42 -> -0.488 | AN6: =Daily_Composite!H43 -> -0.297 | AO6: =Daily_Composite!H44 -> -0.376 | AP6: =Daily_Composite!H45 -> -0.315 | AQ6: =Daily_Composite!H46 -> 0.381 | AR6: =Daily_Composite!H47 -> -0.462 | AS6: =Daily_Composite!H48 -> -0.359 | AT6: =Daily_Composite!H49 -> 0.075 | AU6: =Daily_Composite!H50 -> 0.079 | AV6: =Daily_Composite!H51 -> -0.059 | AW6: =Daily_Composite!H52 -> -0.361 | AX6: =Daily_Composite!H53 -> -0.213 | AY6: =Daily_Composite!H54 -> -0.388 | AZ6: =Daily_Composite!H55 -> -0.44 | BA6: =Daily_Composite!H56 -> 0.277 | BB6: =Daily_Composite!H57 -> -0.516 | BC6: =Daily_Composite!H58 -> -0.537 | BD6: =Daily_Composite!H59 -> -0.085 | BE6: =Daily_Composite!H60 -> -0.498 | BF6: =Daily_Composite!H61 -> -0.474 | BG6: =Daily_Composite!H62 -> -0.131 | BH6: =Daily_Composite!H63 -> -0.383 | BI6: =Daily_Composite!H64 -> -0.115 | BJ6: =Daily_Composite!H65 -> -0.567 | BK6: =Daily_Composite!H66 -> -0.369 | BL6: =Daily_Composite!H67 -> -0.24 | BM6: =Daily_Composite!H68 -> -0.205 | BN6: =Daily_Composite!H69 -> -0.397 | BO6: =Daily_Composite!H70 -> -0.575 | BP6: =Daily_Composite!H71 -> -0.371 | BQ6: =Daily_Composite!H72 -> -0.327 | BR6: =Daily_Composite!H73 -> -0.013 | BS6: =Daily_Composite!H74 -> -0.568 | BT6: =Daily_Composite!H75 -> -0.222 | BU6: =Daily_Composite!H76 -> -0.123 | BV6: =Daily_Composite!H77 -> -0.228 | BW6: =Daily_Composite!H78 -> -0.078 | BX6: =Daily_Composite!H79 -> -0.277 | BY6: =Daily_Composite!H80 -> -0.385 | BZ6: =Daily_Composite!H81 -> -0.312 | CA6: =Daily_Composite!H82 -> -0.324 | CB6: =Daily_Composite!H83 -> 0.106 | CC6: =Daily_Composite!H84 -> -0.513 | CD6: =Daily_Composite!H85 -> 0.187 | CE6: =Daily_Composite!H86 -> -0.257 | CF6: =Daily_Composite!H87 -> 0.233 | CG6: =Daily_Composite!H88 -> -0.426 | CH6: =Daily_Composite!H89 -> -0.535 | CI6: =Daily_Composite!H90 -> -0.169 | CJ6: =Daily_Composite!H91 -> -0.141 | CK6: =Daily_Composite!H92 -> -0.512 | CL6: =Daily_Composite!H93 -> -0.626 | CM6: =Daily_Composite!H94 -> -0.514 | CN6: =Daily_Composite!H95 -> -0.602 | CO6: =Daily_Composite!H96 -> -0.685 | CP6: =Daily_Composite!H97 -> -0.764 | CQ6: =Daily_Composite!H98 -> -0.768 | CR6: =Daily_Composite!H99 -> -0.749 | CS6: =Daily_Composite!H100 -> -0.775 | CT6: =Daily_Composite!H101 -> -0.798 | CU6: =Daily_Composite!H102 -> -0.786 | CV6: =Daily_Composite!H103 -> -0.665 | CW6: =Daily_Composite!H104 -> -0.68 | CX6: =Daily_Composite!H105 -> -0.807 | CY6: =Daily_Composite!H106 -> -0.778 | CZ6: =Daily_Composite!H107 -> -0.698 | DA6: =Daily_Composite!H108 -> -0.798 | DB6: =Daily_Composite!H109 -> -0.798 | DC6: =Daily_Composite!H110 -> -0.771 | DD6: =Daily_Composite!H111 -> -0.792 | DE6: =Daily_Composite!H112 -> -0.789 | DF6: =Daily_Composite!H113 -> -0.488 | DG6: =Daily_Composite!H114 -> -0.5 | DH6: =Daily_Composite!H115 -> -0.558 | DI6: =Daily_Composite!H116 -> -0.77 | DJ6: =Daily_Composite!H117 -> -0.688 | DK6: =Daily_Composite!H118 -> -0.624 | DL6: =Daily_Composite!H119 -> -0.757 | DM6: =Daily_Composite!H120 -> -0.653 | DN6: =Daily_Composite!H121 -> -0.544 | DO6: =Daily_Composite!H122 -> -0.339 | DP6: =Daily_Composite!H123 -> -0.328 | DQ6: =Daily_Composite!H124 -> -0.492 | DR6: =Daily_Composite!H125 -> -0.257 | DS6: =Daily_Composite!H126 -> -0.074 | DT6: =Daily_Composite!H127 -> -0.322 | DU6: =Daily_Composite!H128 -> -0.129 | DV6: =Daily_Composite!H129 -> -0.345 | DW6: =Daily_Composite!H130 -> 0.488 | DX6: =Daily_Composite!H131 -> -0.137 | DY6: =Daily_Composite!H132 -> 0.325 | DZ6: =Daily_Composite!H133 -> 0.008 | EA6: =Daily_Composite!H134 -> -0.302 | EB6: =Daily_Composite!H135 -> 0 | EC6: =Daily_Composite!H136 -> -0.174 | ED6: =Daily_Composite!H137 -> -0.478 | EE6: =Daily_Composite!H138 -> -0.438 | EF6: =Daily_Composite!H139 -> -0.018 | EG6: =Daily_Composite!H140 -> -0.342 | EH6: =Daily_Composite!H141 -> -0.342 | EI6: =Daily_Composite!H142 -> -0.334 | EJ6: =Daily_Composite!H143 -> -0.619 | EK6: =Daily_Composite!H144 -> -0.595 | EL6: =Daily_Composite!H145 -> -0.512 | EM6: =Daily_Composite!H146 -> -0.609 | EN6: =Daily_Composite!H147 -> -0.628 | EO6: =Daily_Composite!H148 -> -0.608 | EP6: =Daily_Composite!H149 -> -0.363 | EQ6: =Daily_Composite!H150 -> -0.503 | ER6: =Daily_Composite!H151 -> -0.528 | ES6: =Daily_Composite!H152 -> -0.593 | ET6: =Daily_Composite!H153 -> -0.529 | EU6: =Daily_Composite!H154 -> -0.543 | EV6: =Daily_Composite!H155 -> -0.442 | EW6: =Daily_Composite!H156 -> -0.602 | EX6: =Daily_Composite!H157 -> -0.38 | EY6: =Daily_Composite!H158 -> -0.332 | EZ6: =Daily_Composite!H159 -> -0.286 | FA6: =Daily_Composite!H160 -> -0.404 | FB6: =Daily_Composite!H161 -> -0.43 | FC6: =Daily_Composite!H162 -> -0.579 | FD6: =Daily_Composite!H163 -> -0.616 | FE6: =Daily_Composite!H164 -> -0.627 | FF6: =Daily_Composite!H165 -> 0.149 | FG6: =Daily_Composite!H166 -> -0.646 | FH6: =Daily_Composite!H167 -> -0.447 | FI6: =Daily_Composite!H168 -> -0.35 | FJ6: =Daily_Composite!H169 -> -0.374 | FK6: =Daily_Composite!H170 -> -0.319 | FL6: =Daily_Composite!H171 -> -0.643 | FM6: =Daily_Composite!H172 -> -0.342 | FN6: =Daily_Composite!H173 -> -0.313 | FO6: =Daily_Composite!H174 -> -0.606 | FP6: =Daily_Composite!H175 -> -0.374 | FQ6: =Daily_Composite!H176 -> -0.218 | FR6: =Daily_Composite!H177 -> 0.3 | FS6: =Daily_Composite!H178 -> -0.234 | FT6: =Daily_Composite!H179 -> -0.593 | FU6: =Daily_Composite!H180 -> -0.268 | FV6: =Daily_Composite!H181 -> -0.159 | FW6: =Daily_Composite!H182 -> -0.443 | FX6: =Daily_Composite!H183 -> -0.178 | FY6: =Daily_Composite!H184 -> -0.424 | FZ6: =Daily_Composite!H185 -> -0.071 | GA6: =Daily_Composite!H186 -> 0.233 | GB6: =Daily_Composite!H187 -> 0.178 | GC6: =Daily_Composite!H188 -> -0.288 | GD6: =Daily_Composite!H189 -> -0.116 | GE6: =Daily_Composite!H190 -> -0.157 | GF6: =Daily_Composite!H191 -> -0.147 | GG6: =Daily_Composite!H192 -> -0.453 | GH6: =Daily_Composite!H193 -> -0.146 | GI6: =Daily_Composite!H194 -> -0.051 | GJ6: =Daily_Composite!H195 -> -0.023 | GK6: =Daily_Composite!H196 -> 0.421 | GL6: =Daily_Composite!H197 -> -0.006 | GM6: =Daily_Composite!H198 -> -0.382 | GN6: =Daily_Composite!H199 -> 0.3 | GO6: =Daily_Composite!H200 -> 0.009 | GP6: =Daily_Composite!H201 -> -0.303 | GQ6: =Daily_Composite!H202 -> -0.328 | GR6: =Daily_Composite!H203 -> 0.254 | GS6: =Daily_Composite!H204 -> -0.111 | GT6: =Daily_Composite!H205 -> -0.074 | GU6: =Daily_Composite!H206 -> -0.445 | GV6: =Daily_Composite!H207 -> -0.247 | GW6: =Daily_Composite!H208 -> -0.088 | GX6: =Daily_Composite!H209 -> -0.47 | GY6: =Daily_Composite!H210 -> -0.459 | GZ6: =Daily_Composite!H211 -> -0.375 | HA6: =Daily_Composite!H212 -> -0.007 | HB6: =Daily_Composite!H213 -> -0.4 | HC6: =Daily_Composite!H214 -> -0.645 | HD6: =Daily_Composite!H215 -> -0.438 | HE6: =Daily_Composite!H216 -> -0.262 | HF6: =Daily_Composite!H217 -> -0.485 | HG6: =Daily_Composite!H218 -> -0.542 | HH6: =Daily_Composite!H219 -> -0.592 | HI6: =Daily_Composite!H220 -> -0.554 | HJ6: =Daily_Composite!H221 -> -0.569 | HK6: =Daily_Composite!H222 -> -0.499 | HL6: =Daily_Composite!H223 -> -0.579 | HM6: =Daily_Composite!H224 -> -0.283 | HN6: =Daily_Composite!H225 -> -0.617 | HO6: =Daily_Composite!H226 -> -0.533 | HP6: =Daily_Composite!H227 -> -0.416 | HQ6: =Daily_Composite!H228 -> -0.596 | HR6: =Daily_Composite!H229 -> -0.16 | HS6: =Daily_Composite!H230 -> 0.124 | HT6: =Daily_Composite!H231 -> -0.295 | HU6: =Daily_Composite!H232 -> -0.395 | HV6: =Daily_Composite!H233 -> -0.26 | HW6: =Daily_Composite!H234 -> -0.419 | HX6: =Daily_Composite!H235 -> -0.384 | HY6: =Daily_Composite!H236 -> -0.252 | HZ6: =Daily_Composite!H237 -> -0.257 | IA6: =Daily_Composite!H238 -> 0.166 | IB6: =Daily_Composite!H239 -> 0.438 | IC6: =Daily_Composite!H240 -> 0.06 | ID6: =Daily_Composite!H241 -> 0.333 | IE6: =Daily_Composite!H242 -> -0.026 | IF6: =Daily_Composite!H243 -> -0.302 | IG6: =Daily_Composite!H244 -> -0.172 | IH6: =Daily_Composite!H245 -> -0.119 | II6: =Daily_Composite!H246 -> 0.019 | IJ6: =Daily_Composite!H247 -> 0.466 | IK6: =Daily_Composite!H248 -> 0.306 | IL6: =Daily_Composite!H249 -> 0.557 | IM6: =Daily_Composite!H250 -> -0.019 | IN6: =Daily_Composite!H251 -> 0.549 | IO6: =Daily_Composite!H252 -> 0.227 | IP6: =Daily_Composite!H253 -> 0.044 | IQ6: =Daily_Composite!H254 -> 0.017 | IR6: =Daily_Composite!H255 -> 0.305 | IS6: =Daily_Composite!H256 -> -0.222 | IT6: =Daily_Composite!H257 -> 0.464 | IU6: =Daily_Composite!H258 -> 0.131 | IV6: =Daily_Composite!H259 -> 0.492 | IW6: =Daily_Composite!H260 -> 0.114 | IX6: =Daily_Composite!H261 -> 0.121 | IY6: =Daily_Composite!H262 -> 0.031 | IZ6: =Daily_Composite!H263 -> -0.125 | JA6: =Daily_Composite!H264 -> -0.111 | JB6: =Daily_Composite!H265 -> -0.104 | JC6: =Daily_Composite!H266 -> 0.391 | JD6: =Daily_Composite!H267 -> -0.05 | JE6: =Daily_Composite!H268 -> 0.243 | JF6: =Daily_Composite!H269 -> -0.129 | JG6: =Daily_Composite!H270 -> -0.237 | JH6: =Daily_Composite!H271 -> -0.48 | JI6: =Daily_Composite!H272 -> -0.177 | JJ6: =Daily_Composite!H273 -> -0.315 | JK6: =Daily_Composite!H274 -> -0.458 | JL6: =Daily_Composite!H275 -> -0.637 | JM6: =Daily_Composite!H276 -> 0.053 | JN6: =Daily_Composite!H277 -> -0.403 | JO6: =Daily_Composite!H278 -> -0.712 | JP6: =Daily_Composite!H279 -> -0.34 | JQ6: =Daily_Composite!H280 -> -0.46 | JR6: =Daily_Composite!H281 -> -0.271 | JS6: =Daily_Composite!H282 -> 0.114 | JT6: =Daily_Composite!H283 -> 0.108 | JU6: =Daily_Composite!H284 -> -0.377 | JV6: =Daily_Composite!H285 -> 0.331 | JW6: =Daily_Composite!H286 -> 0.243 | JX6: =Daily_Composite!H287 -> -0.038 | JY6: =Daily_Composite!H288 -> 0.143 | JZ6: =Daily_Composite!H289 -> 0.039 | KA6: =Daily_Composite!H290 -> -0.024 | KB6: =Daily_Composite!H291 -> -0.007 | KC6: =Daily_Composite!H292 -> -0.307 | KD6: =Daily_Composite!H293 -> 0.331 | KE6: =Daily_Composite!H294 -> -0.241 | KF6: =Daily_Composite!H295 -> -0.016 | KG6: =Daily_Composite!H296 -> -0.026 | KH6: =Daily_Composite!H297 -> -0.464 | KI6: =Daily_Composite!H298 -> -0.311 | KJ6: =Daily_Composite!H299 -> -0.267 | KK6: =Daily_Composite!H300 -> -0.455 | KL6: =Daily_Composite!H301 -> -0.441 | KM6: =Daily_Composite!H302 -> -0.265 | KN6: =Daily_Composite!H303 -> 0.322 | KO6: =Daily_Composite!H304 -> -0.371 | KP6: =Daily_Composite!H305 -> -0.355 | KQ6: =Daily_Composite!H306 -> -0.051 | KR6: =Daily_Composite!H307 -> -0.35 | KS6: =Daily_Composite!H308 -> -0.424 | KT6: =Daily_Composite!H309 -> -0.354 | KU6: =Daily_Composite!H310 -> -0.561 | KV6: =Daily_Composite!H311 -> -0.608 | KW6: =Daily_Composite!H312 -> -0.132 | KX6: =Daily_Composite!H313 -> -0.138 | KY6: =Daily_Composite!H314 -> -0.595 | KZ6: =Daily_Composite!H315 -> -0.357 | LA6: =Daily_Composite!H316 -> -0.487 | LB6: =Daily_Composite!H317 -> -0.435 | LC6: =Daily_Composite!H318 -> -0.407 | LD6: =Daily_Composite!H319 -> -0.055 | LE6: =Daily_Composite!H320 -> -0.361 | LF6: =Daily_Composite!H321 -> 0.208 | LG6: =Daily_Composite!H322 -> 0.257 | LH6: =Daily_Composite!H323 -> 0.598 | LI6: =Daily_Composite!H324 -> 0.006 | LJ6: =Daily_Composite!H325 -> -0.203 | LK6: =Daily_Composite!H326 -> 0.096 | LL6: =Daily_Composite!H327 -> 0.282 | LM6: =Daily_Composite!H328 -> 0.55 | LN6: =Daily_Composite!H329 -> 0.237 | LO6: =Daily_Composite!H330 -> -0.38 | LP6: =Daily_Composite!H331 -> 0.153 | LQ6: =Daily_Composite!H332 -> 0.019 | LR6: =Daily_Composite!H333 -> 0.164 | LS6: =Daily_Composite!H334 -> -0.113 | LT6: =Daily_Composite!H335 -> -0.415 | LU6: =Daily_Composite!H336 -> -0.144 | LV6: =Daily_Composite!H337 -> -0.147 | LW6: =Daily_Composite!H338 -> -0.17 | LX6: =Daily_Composite!H339 -> -0.174 | LY6: =Daily_Composite!H340 -> -0.016 | LZ6: =Daily_Composite!H341 -> -0.13 | MA6: =Daily_Composite!H342 -> -0.176 | MB6: =Daily_Composite!H343 -> -0.315 | MC6: =Daily_Composite!H344 -> -0.079 | MD6: =Daily_Composite!H345 -> -0.069 | ME6: =Daily_Composite!H346 -> -0.025 | MF6: =Daily_Composite!H347 -> 0.654 | MG6: =Daily_Composite!H348 -> 0.662 | MH6: =Daily_Composite!H349 -> 0.479 | MI6: =Daily_Composite!H350 -> 0.727 | MJ6: =Daily_Composite!H351 -> 0.683 | MK6: =Daily_Composite!H352 -> 0.47 | ML6: =Daily_Composite!H353 -> 0.574 | MM6: =Daily_Composite!H354 -> 0.687 | MN6: =Daily_Composite!H355 -> 0.596 | MO6: =Daily_Composite!H356 -> 0.71 | MP6: =Daily_Composite!H357 -> 0.69 | MQ6: =Daily_Composite!H358 -> 0.664 | MR6: =Daily_Composite!H359 -> 0.194 | MS6: =Daily_Composite!H360 -> 0.57 | MT6: =Daily_Composite!H361 -> 0.375 | MU6: =Daily_Composite!H362 -> 0.4 | MV6: =Daily_Composite!H363 -> 0.077 | MW6: =Daily_Composite!H364 -> 0.065 | MX6: =Daily_Composite!H365 -> 0.118 | MY6: =Daily_Composite!H366 -> 0.549 | MZ6: =Daily_Composite!H367 -> 0.476 | NA6: =Daily_Composite!H368 -> 0.142 | NB6: =Daily_Composite!H369 -> 0.132
A7: Automobile | B7: =Daily_Composite!I5 -> 0.011 | C7: =Daily_Composite!I6 -> -0.099 | D7: =Daily_Composite!I7 -> 0.084 | E7: =Daily_Composite!I8 -> 0.01 | F7: =Daily_Composite!I9 -> -0.026 | G7: =Daily_Composite!I10 -> -0.134 | H7: =Daily_Composite!I11 -> -0.126 | I7: =Daily_Composite!I12 -> -0.468 | J7: =Daily_Composite!I13 -> -0.089 | K7: =Daily_Composite!I14 -> -0.086 | L7: =Daily_Composite!I15 -> -0.084 | M7: =Daily_Composite!I16 -> -0.214 | N7: =Daily_Composite!I17 -> -0.081 | O7: =Daily_Composite!I18 -> -0.081 | P7: =Daily_Composite!I19 -> -0.213 | Q7: =Daily_Composite!I20 -> -0.207 | R7: =Daily_Composite!I21 -> 0.15 | S7: =Daily_Composite!I22 -> -0.424 | T7: =Daily_Composite!I23 -> 0.002 | U7: =Daily_Composite!I24 -> 0.002 | V7: =Daily_Composite!I25 -> 0.002 | W7: =Daily_Composite!I26 -> -0.227 | X7: =Daily_Composite!I27 -> 0.058 | Y7: =Daily_Composite!I28 -> 0.045 | Z7: =Daily_Composite!I29 -> 0.053 | AA7: =Daily_Composite!I30 -> 0.085 | AB7: =Daily_Composite!I31 -> -0.294 | AC7: =Daily_Composite!I32 -> -0.127 | AD7: =Daily_Composite!I33 -> 0.119 | AE7: =Daily_Composite!I34 -> 0.151 | AF7: =Daily_Composite!I35 -> 0.623 | AG7: =Daily_Composite!I36 -> 0.252 | AH7: =Daily_Composite!I37 -> 0.214 | AI7: =Daily_Composite!I38 -> 0.226 | AJ7: =Daily_Composite!I39 -> 0.48 | AK7: =Daily_Composite!I40 -> 0.209 | AL7: =Daily_Composite!I41 -> 0.179 | AM7: =Daily_Composite!I42 -> 0.118 | AN7: =Daily_Composite!I43 -> 0.445 | AO7: =Daily_Composite!I44 -> 0.107 | AP7: =Daily_Composite!I45 -> 0.116 | AQ7: =Daily_Composite!I46 -> 0.217 | AR7: =Daily_Composite!I47 -> 0.198 | AS7: =Daily_Composite!I48 -> 0.135 | AT7: =Daily_Composite!I49 -> -0.289 | AU7: =Daily_Composite!I50 -> 0.119 | AV7: =Daily_Composite!I51 -> 0.115 | AW7: =Daily_Composite!I52 -> 0.122 | AX7: =Daily_Composite!I53 -> 0.293 | AY7: =Daily_Composite!I54 -> 0.204 | AZ7: =Daily_Composite!I55 -> 0.113 | BA7: =Daily_Composite!I56 -> 0.128 | BB7: =Daily_Composite!I57 -> 0.178 | BC7: =Daily_Composite!I58 -> 0.205 | BD7: =Daily_Composite!I59 -> 0.54 | BE7: =Daily_Composite!I60 -> 0.289 | BF7: =Daily_Composite!I61 -> 0.148 | BG7: =Daily_Composite!I62 -> 0.608 | BH7: =Daily_Composite!I63 -> 0.08 | BI7: =Daily_Composite!I64 -> 0.085 | BJ7: =Daily_Composite!I65 -> 0.101 | BK7: =Daily_Composite!I66 -> 0.053 | BL7: =Daily_Composite!I67 -> 0.334 | BM7: =Daily_Composite!I68 -> 0.038 | BN7: =Daily_Composite!I69 -> 0.073 | BO7: =Daily_Composite!I70 -> 0.031 | BP7: =Daily_Composite!I71 -> 0.254 | BQ7: =Daily_Composite!I72 -> -0.019 | BR7: =Daily_Composite!I73 -> -0.016 | BS7: =Daily_Composite!I74 -> 0.164 | BT7: =Daily_Composite!I75 -> 0.136 | BU7: =Daily_Composite!I76 -> -0.13 | BV7: =Daily_Composite!I77 -> -0.08 | BW7: =Daily_Composite!I78 -> -0.061 | BX7: =Daily_Composite!I79 -> -0.07 | BY7: =Daily_Composite!I80 -> -0.07 | BZ7: =Daily_Composite!I81 -> 0.437 | CA7: =Daily_Composite!I82 -> -0.075 | CB7: =Daily_Composite!I83 -> 0.002 | CC7: =Daily_Composite!I84 -> -0.038 | CD7: =Daily_Composite!I85 -> -0.013 | CE7: =Daily_Composite!I86 -> 0.348 | CF7: =Daily_Composite!I87 -> 0.364 | CG7: =Daily_Composite!I88 -> -0.008 | CH7: =Daily_Composite!I89 -> 0.006 | CI7: =Daily_Composite!I90 -> 0.38 | CJ7: =Daily_Composite!I91 -> 0.007 | CK7: =Daily_Composite!I92 -> 0.04 | CL7: =Daily_Composite!I93 -> 0.048 | CM7: =Daily_Composite!I94 -> 0.5 | CN7: =Daily_Composite!I95 -> 0.055 | CO7: =Daily_Composite!I96 -> 0.023 | CP7: =Daily_Composite!I97 -> 0.027 | CQ7: =Daily_Composite!I98 -> -0.407 | CR7: =Daily_Composite!I99 -> 0.004 | CS7: =Daily_Composite!I100 -> 0.007 | CT7: =Daily_Composite!I101 -> -0.08 | CU7: =Daily_Composite!I102 -> -0.165 | CV7: =Daily_Composite!I103 -> -0.49 | CW7: =Daily_Composite!I104 -> -0.522 | CX7: =Daily_Composite!I105 -> -0.105 | CY7: =Daily_Composite!I106 -> -0.177 | CZ7: =Daily_Composite!I107 -> -0.221 | DA7: =Daily_Composite!I108 -> -0.396 | DB7: =Daily_Composite!I109 -> -0.14 | DC7: =Daily_Composite!I110 -> -0.117 | DD7: =Daily_Composite!I111 -> -0.115 | DE7: =Daily_Composite!I112 -> -0.056 | DF7: =Daily_Composite!I113 -> -0.504 | DG7: =Daily_Composite!I114 -> -0.13 | DH7: =Daily_Composite!I115 -> 0.019 | DI7: =Daily_Composite!I116 -> -0.102 | DJ7: =Daily_Composite!I117 -> -0.253 | DK7: =Daily_Composite!I118 -> 0.046 | DL7: =Daily_Composite!I119 -> 0.06 | DM7: =Daily_Composite!I120 -> 0.071 | DN7: =Daily_Composite!I121 -> 0.082 | DO7: =Daily_Composite!I122 -> 0.02 | DP7: =Daily_Composite!I123 -> 0.107 | DQ7: =Daily_Composite!I124 -> -0.005 | DR7: =Daily_Composite!I125 -> 0.458 | DS7: =Daily_Composite!I126 -> 0.098 | DT7: =Daily_Composite!I127 -> 0.115 | DU7: =Daily_Composite!I128 -> 0.427 | DV7: =Daily_Composite!I129 -> 0.406 | DW7: =Daily_Composite!I130 -> 0.43 | DX7: =Daily_Composite!I131 -> 0.514 | DY7: =Daily_Composite!I132 -> -0.072 | DZ7: =Daily_Composite!I133 -> -0.017 | EA7: =Daily_Composite!I134 -> -0.006 | EB7: =Daily_Composite!I135 -> 0.4 | EC7: =Daily_Composite!I136 -> 0.015 | ED7: =Daily_Composite!I137 -> 0.015 | EE7: =Daily_Composite!I138 -> -0.009 | EF7: =Daily_Composite!I139 -> -0.003 | EG7: =Daily_Composite!I140 -> 0.508 | EH7: =Daily_Composite!I141 -> 0.187 | EI7: =Daily_Composite!I142 -> 0.191 | EJ7: =Daily_Composite!I143 -> 0.036 | EK7: =Daily_Composite!I144 -> -0.299 | EL7: =Daily_Composite!I145 -> 0.045 | EM7: =Daily_Composite!I146 -> 0.038 | EN7: =Daily_Composite!I147 -> 0.041 | EO7: =Daily_Composite!I148 -> 0.053 | EP7: =Daily_Composite!I149 -> 0.285 | EQ7: =Daily_Composite!I150 -> 0.086 | ER7: =Daily_Composite!I151 -> 0.015 | ES7: =Daily_Composite!I152 -> 0.015 | ET7: =Daily_Composite!I153 -> -0.394 | EU7: =Daily_Composite!I154 -> -0.074 | EV7: =Daily_Composite!I155 -> -0.078 | EW7: =Daily_Composite!I156 -> 0.134 | EX7: =Daily_Composite!I157 -> 0.077 | EY7: =Daily_Composite!I158 -> -0.392 | EZ7: =Daily_Composite!I159 -> -0.085 | FA7: =Daily_Composite!I160 -> -0.066 | FB7: =Daily_Composite!I161 -> -0.037 | FC7: =Daily_Composite!I162 -> 0.258 | FD7: =Daily_Composite!I163 -> -0.29 | FE7: =Daily_Composite!I164 -> -0.061 | FF7: =Daily_Composite!I165 -> -0.06 | FG7: =Daily_Composite!I166 -> -0.057 | FH7: =Daily_Composite!I167 -> -0.028 | FI7: =Daily_Composite!I168 -> -0.386 | FJ7: =Daily_Composite!I169 -> -0.167 | FK7: =Daily_Composite!I170 -> -0.021 | FL7: =Daily_Composite!I171 -> -0.017 | FM7: =Daily_Composite!I172 -> -0.087 | FN7: =Daily_Composite!I173 -> -0.007 | FO7: =Daily_Composite!I174 -> 0.014 | FP7: =Daily_Composite!I175 -> 0.035 | FQ7: =Daily_Composite!I176 -> -0.142 | FR7: =Daily_Composite!I177 -> -0.109 | FS7: =Daily_Composite!I178 -> -0.134 | FT7: =Daily_Composite!I179 -> -0.138 | FU7: =Daily_Composite!I180 -> -0.525 | FV7: =Daily_Composite!I181 -> -0.255 | FW7: =Daily_Composite!I182 -> -0.293 | FX7: =Daily_Composite!I183 -> -0.449 | FY7: =Daily_Composite!I184 -> -0.425 | FZ7: =Daily_Composite!I185 -> -0.559 | GA7: =Daily_Composite!I186 -> -0.295 | GB7: =Daily_Composite!I187 -> -0.33 | GC7: =Daily_Composite!I188 -> -0.278 | GD7: =Daily_Composite!I189 -> -0.175 | GE7: =Daily_Composite!I190 -> 0.217 | GF7: =Daily_Composite!I191 -> -0.062 | GG7: =Daily_Composite!I192 -> -0.076 | GH7: =Daily_Composite!I193 -> -0.141 | GI7: =Daily_Composite!I194 -> -0.154 | GJ7: =Daily_Composite!I195 -> 0.255 | GK7: =Daily_Composite!I196 -> -0.168 | GL7: =Daily_Composite!I197 -> -0.185 | GM7: =Daily_Composite!I198 -> -0.215 | GN7: =Daily_Composite!I199 -> -0.454 | GO7: =Daily_Composite!I200 -> -0.224 | GP7: =Daily_Composite!I201 -> -0.201 | GQ7: =Daily_Composite!I202 -> -0.177 | GR7: =Daily_Composite!I203 -> -0.153 | GS7: =Daily_Composite!I204 -> -0.209 | GT7: =Daily_Composite!I205 -> -0.01 | GU7: =Daily_Composite!I206 -> -0.088 | GV7: =Daily_Composite!I207 -> -0.165 | GW7: =Daily_Composite!I208 -> -0.089 | GX7: =Daily_Composite!I209 -> -0.091 | GY7: =Daily_Composite!I210 -> -0.069 | GZ7: =Daily_Composite!I211 -> -0.205 | HA7: =Daily_Composite!I212 -> -0.233 | HB7: =Daily_Composite!I213 -> -0.461 | HC7: =Daily_Composite!I214 -> -0.097 | HD7: =Daily_Composite!I215 -> -0.102 | HE7: =Daily_Composite!I216 -> -0.107 | HF7: =Daily_Composite!I217 -> -0.365 | HG7: =Daily_Composite!I218 -> -0.03 | HH7: =Daily_Composite!I219 -> -0.066 | HI7: =Daily_Composite!I220 -> -0.142 | HJ7: =Daily_Composite!I221 -> -0.142 | HK7: =Daily_Composite!I222 -> -0.151 | HL7: =Daily_Composite!I223 -> -0.069 | HM7: =Daily_Composite!I224 -> -0.495 | HN7: =Daily_Composite!I225 -> -0.189 | HO7: =Daily_Composite!I226 -> -0.339 | HP7: =Daily_Composite!I227 -> -0.207 | HQ7: =Daily_Composite!I228 -> -0.207 | HR7: =Daily_Composite!I229 -> -0.23 | HS7: =Daily_Composite!I230 -> -0.254 | HT7: =Daily_Composite!I231 -> -0.501 | HU7: =Daily_Composite!I232 -> -0.139 | HV7: =Daily_Composite!I233 -> -0.297 | HW7: =Daily_Composite!I234 -> -0.281 | HX7: =Daily_Composite!I235 -> -0.405 | HY7: =Daily_Composite!I236 -> -0.276 | HZ7: =Daily_Composite!I237 -> -0.275 | IA7: =Daily_Composite!I238 -> -0.432 | IB7: =Daily_Composite!I239 -> -0.41 | IC7: =Daily_Composite!I240 -> -0.622 | ID7: =Daily_Composite!I241 -> -0.151 | IE7: =Daily_Composite!I242 -> -0.164 | IF7: =Daily_Composite!I243 -> -0.219 | IG7: =Daily_Composite!I244 -> -0.449 | IH7: =Daily_Composite!I245 -> 0.161 | II7: =Daily_Composite!I246 -> -0.084 | IJ7: =Daily_Composite!I247 -> -0.084 | IK7: =Daily_Composite!I248 -> -0.125 | IL7: =Daily_Composite!I249 -> -0.129 | IM7: =Daily_Composite!I250 -> 0.083 | IN7: =Daily_Composite!I251 -> 0.197 | IO7: =Daily_Composite!I252 -> -0.069 | IP7: =Daily_Composite!I253 -> -0.133 | IQ7: =Daily_Composite!I254 -> 0.137 | IR7: =Daily_Composite!I255 -> -0.135 | IS7: =Daily_Composite!I256 -> -0.23 | IT7: =Daily_Composite!I257 -> -0.233 | IU7: =Daily_Composite!I258 -> -0.317 | IV7: =Daily_Composite!I259 -> -0.232 | IW7: =Daily_Composite!I260 -> -0.091 | IX7: =Daily_Composite!I261 -> -0.124 | IY7: =Daily_Composite!I262 -> -0.525 | IZ7: =Daily_Composite!I263 -> -0.221 | JA7: =Daily_Composite!I264 -> -0.222 | JB7: =Daily_Composite!I265 -> -0.287 | JC7: =Daily_Composite!I266 -> -0.48 | JD7: =Daily_Composite!I267 -> -0.324 | JE7: =Daily_Composite!I268 -> -0.213 | JF7: =Daily_Composite!I269 -> -0.23 | JG7: =Daily_Composite!I270 -> -0.126 | JH7: =Daily_Composite!I271 -> -0.229 | JI7: =Daily_Composite!I272 -> -0.581 | JJ7: =Daily_Composite!I273 -> -0.228 | JK7: =Daily_Composite!I274 -> -0.227 | JL7: =Daily_Composite!I275 -> -0.096 | JM7: =Daily_Composite!I276 -> -0.1 | JN7: =Daily_Composite!I277 -> -0.135 | JO7: =Daily_Composite!I278 -> -0.09 | JP7: =Daily_Composite!I279 -> -0.215 | JQ7: =Daily_Composite!I280 -> -0.11 | JR7: =Daily_Composite!I281 -> -0.559 | JS7: =Daily_Composite!I282 -> -0.186 | JT7: =Daily_Composite!I283 -> -0.208 | JU7: =Daily_Composite!I284 -> -0.208 | JV7: =Daily_Composite!I285 -> -0.209 | JW7: =Daily_Composite!I286 -> -0.21 | JX7: =Daily_Composite!I287 -> -0.21 | JY7: =Daily_Composite!I288 -> -0.085 | JZ7: =Daily_Composite!I289 -> 0.085 | KA7: =Daily_Composite!I290 -> -0.211 | KB7: =Daily_Composite!I291 -> -0.211 | KC7: =Daily_Composite!I292 -> -0.288 | KD7: =Daily_Composite!I293 -> -0.355 | KE7: =Daily_Composite!I294 -> 0.179 | KF7: =Daily_Composite!I295 -> 0.19 | KG7: =Daily_Composite!I296 -> -0.225 | KH7: =Daily_Composite!I297 -> -0.245 | KI7: =Daily_Composite!I298 -> -0.226 | KJ7: =Daily_Composite!I299 -> -0.487 | KK7: =Daily_Composite!I300 -> -0.27 | KL7: =Daily_Composite!I301 -> -0.275 | KM7: =Daily_Composite!I302 -> -0.255 | KN7: =Daily_Composite!I303 -> -0.258 | KO7: =Daily_Composite!I304 -> -0.24 | KP7: =Daily_Composite!I305 -> -0.36 | KQ7: =Daily_Composite!I306 -> -0.197 | KR7: =Daily_Composite!I307 -> -0.287 | KS7: =Daily_Composite!I308 -> -0.513 | KT7: =Daily_Composite!I309 -> -0.162 | KU7: =Daily_Composite!I310 -> -0.195 | KV7: =Daily_Composite!I311 -> -0.225 | KW7: =Daily_Composite!I312 -> -0.224 | KX7: =Daily_Composite!I313 -> -0.346 | KY7: =Daily_Composite!I314 -> -0.198 | KZ7: =Daily_Composite!I315 -> -0.194 | LA7: =Daily_Composite!I316 -> -0.189 | LB7: =Daily_Composite!I317 -> -0.025 | LC7: =Daily_Composite!I318 -> -0.064 | LD7: =Daily_Composite!I319 -> -0.41 | LE7: =Daily_Composite!I320 -> -0.476 | LF7: =Daily_Composite!I321 -> -0.428 | LG7: =Daily_Composite!I322 -> -0.294 | LH7: =Daily_Composite!I323 -> -0.124 | LI7: =Daily_Composite!I324 -> -0.138 | LJ7: =Daily_Composite!I325 -> -0.163 | LK7: =Daily_Composite!I326 -> -0.583 | LL7: =Daily_Composite!I327 -> -0.137 | LM7: =Daily_Composite!I328 -> -0.133 | LN7: =Daily_Composite!I329 -> -0.15 | LO7: =Daily_Composite!I330 -> -0.146 | LP7: =Daily_Composite!I331 -> -0.119 | LQ7: =Daily_Composite!I332 -> 0.141 | LR7: =Daily_Composite!I333 -> 0.145 | LS7: =Daily_Composite!I334 -> -0.136 | LT7: =Daily_Composite!I335 -> -0.152 | LU7: =Daily_Composite!I336 -> -0.565 | LV7: =Daily_Composite!I337 -> -0.125 | LW7: =Daily_Composite!I338 -> -0.103 | LX7: =Daily_Composite!I339 -> -0.139 | LY7: =Daily_Composite!I340 -> -0.331 | LZ7: =Daily_Composite!I341 -> -0.135 | MA7: =Daily_Composite!I342 -> -0.13 | MB7: =Daily_Composite!I343 -> -0.126 | MC7: =Daily_Composite!I344 -> -0.537 | MD7: =Daily_Composite!I345 -> -0.067 | ME7: =Daily_Composite!I346 -> -0.073 | MF7: =Daily_Composite!I347 -> -0.409 | MG7: =Daily_Composite!I348 -> -0.388 | MH7: =Daily_Composite!I349 -> -0.261 | MI7: =Daily_Composite!I350 -> -0.044 | MJ7: =Daily_Composite!I351 -> 0.014 | MK7: =Daily_Composite!I352 -> -0.013 | ML7: =Daily_Composite!I353 -> -0.013 | MM7: =Daily_Composite!I354 -> -0.013 | MN7: =Daily_Composite!I355 -> -0.146 | MO7: =Daily_Composite!I356 -> -0.118 | MP7: =Daily_Composite!I357 -> -0.04 | MQ7: =Daily_Composite!I358 -> -0.018 | MR7: =Daily_Composite!I359 -> -0.164 | MS7: =Daily_Composite!I360 -> -0.128 | MT7: =Daily_Composite!I361 -> -0.098 | MU7: =Daily_Composite!I362 -> -0.139 | MV7: =Daily_Composite!I363 -> -0.131 | MW7: =Daily_Composite!I364 -> -0.13 | MX7: =Daily_Composite!I365 -> -0.156 | MY7: =Daily_Composite!I366 -> -0.237 | MZ7: =Daily_Composite!I367 -> -0.235 | NA7: =Daily_Composite!I368 -> -0.183 | NB7: =Daily_Composite!I369 -> -0.21
